Workbook

Sheet Tổng quan
A1: EduMentor AI — Checklist thay đổi đặc tả API (§2 và §10)
A2: Mục đích: giúp cả nhóm kiểm tra những chỗ còn thiếu hoặc mâu thuẫn giữa bảng endpoint và thiết kế cơ sở dữ liệu, rồi thống nhất cách sửa.
A4: CÁCH DÙNG (5 bước)
A5: 1. Mở sheet "Danh sách thay đổi" và đọc từng dòng (cột "Đặc tả chi tiết" nói rõ cần làm gì).
A6: 2. Gặp chỗ khó (có mã G… ở cột cuối) → bấm vào mã để xem giải thích và ví dụ ở sheet "Giải thích".
A7: 3. Cả nhóm thống nhất → chọn ☑ ở cột "Nhóm đồng ý". Chưa đồng ý thì để ☐ và ghi lý do vào cột Ghi chú.
A8: 4. Các câu hỏi chưa có đáp án nằm ở sheet "Quyết định cần chốt": chọn A / B / Khác rồi tick "Đã chốt".
A9: 5. Sau khi sửa tài liệu/code, tick cột "Đã cập nhật xong" (sheet Danh sách thay đổi) và "Đã sửa xong" (sheet File cần sửa).
A11: CHÚ GIẢI
A12: Bắt buộc | B12: Thiếu thì thiết kế bị hỏng hoặc mâu thuẫn; nên làm trong phiên bản đầu.
A13: Nên có | B13: Làm cho hệ thống đầy đủ và dễ dùng hơn.
A14: Tùy chọn | B14: Có thể để sau nếu hết thời gian.
A15: Dễ / Trung bình / Khó | B15: Độ khó khi lập trình: Dễ ≈ vài giờ; Trung bình ≈ 1–2 ngày; Khó ≈ nhiều ngày hoặc cần phối hợp nhiều người.
A16: Ô vàng nhạt | B16: Ô để nhóm nhập: tick ☐/☑, chọn A/B, hoặc viết ghi chú.
A18: TIẾN ĐỘ CHUNG (tự tính)
A19: Chỉ số | B19: Số lượng | C19: Tỉ lệ
A20: Tổng số hạng mục thay đổi | B20: =COUNTA('Danh sách thay đổi'!$A$5:$A$33) -> 29
A21: Nhóm đã đồng ý (☑) | B21: =COUNTIF('Danh sách thay đổi'!$J$5:$J$33,"☑") -> 21 | C21: =IFERROR(B21/B20,0) -> 0.72413793
A22: Đã cập nhật xong tài liệu/code | B22: =COUNTIF('Danh sách thay đổi'!$K$5:$K$33,"☑") -> 0 | C22: =IFERROR(B22/B20,0) -> 0
A23: Hạng mục "Bắt buộc" chưa được đồng ý | B23: =COUNTIFS('Danh sách thay đổi'!$G$5:$G$33,"Bắt buộc",'Danh sách thay đổi'!$J$5:$J$33,"☐") -> 4
A24: Hạng mục "Khó" chưa được đồng ý | B24: =COUNTIFS('Danh sách thay đổi'!$H$5:$H$33,"Khó",'Danh sách thay đổi'!$J$5:$J$33,"☐") -> 1
A25: Quyết định cần chốt (tổng) | B25: =COUNTA('Quyết định cần chốt'!$A$5:$A$15) -> 11
A26: Quyết định đã chốt (☑) | B26: =COUNTIF('Quyết định cần chốt'!$I$5:$I$15,"☑") -> 11 | C26: =IFERROR(B26/B25,0) -> 1
A27: File cần sửa (tổng) | B27: =COUNTA('File cần sửa'!$B$5:$B$13) -> 9
A28: File đã sửa xong (☑) | B28: =COUNTIF('File cần sửa'!$F$5:$F$13,"☑") -> 0 | C28: =IFERROR(B28/B27,0) -> 0
A29: Endpoint đã làm xong (☑) | B29: =COUNTIF('Endpoint (bản mới)'!$K$5:$K$40,"☑") -> 0 | C29: =IFERROR(B29/COUNTA('Endpoint (bản mới)'!$C$5:$C$40),0) -> 0
A31: THEO MỨC ĐỘ ƯU TIÊN
A32: Mức độ | B32: Số hạng mục | C32: Đã đồng ý | D32: Đã cập nhật
A33: Bắt buộc | B33: =COUNTIF('Danh sách thay đổi'!$G$5:$G$33,"Bắt buộc") -> 15 | C33: =COUNTIFS('Danh sách thay đổi'!$G$5:$G$33,"Bắt buộc",'Danh sách thay đổi'!$J$5:$J$33,"☑") -> 11 | D33: =COUNTIFS('Danh sách thay đổi'!$G$5:$G$33,"Bắt buộc",'Danh sách thay đổi'!$K$5:$K$33,"☑") -> 0
A34: Nên có | B34: =COUNTIF('Danh sách thay đổi'!$G$5:$G$33,"Nên có") -> 11 | C34: =COUNTIFS('Danh sách thay đổi'!$G$5:$G$33,"Nên có",'Danh sách thay đổi'!$J$5:$J$33,"☑") -> 8 | D34: =COUNTIFS('Danh sách thay đổi'!$G$5:$G$33,"Nên có",'Danh sách thay đổi'!$K$5:$K$33,"☑") -> 0
A35: Tùy chọn | B35: =COUNTIF('Danh sách thay đổi'!$G$5:$G$33,"Tùy chọn") -> 3 | C35: =COUNTIFS('Danh sách thay đổi'!$G$5:$G$33,"Tùy chọn",'Danh sách thay đổi'!$J$5:$J$33,"☑") -> 2 | D35: =COUNTIFS('Danh sách thay đổi'!$G$5:$G$33,"Tùy chọn",'Danh sách thay đổi'!$K$5:$K$33,"☑") -> 0
A37: THEO ĐỘ KHÓ
A38: Độ khó | B38: Số hạng mục | C38: Đã đồng ý | D38: Đã cập nhật
A39: Dễ | B39: =COUNTIF('Danh sách thay đổi'!$H$5:$H$33,"Dễ") -> 19 | C39: =COUNTIFS('Danh sách thay đổi'!$H$5:$H$33,"Dễ",'Danh sách thay đổi'!$J$5:$J$33,"☑") -> 12 | D39: =COUNTIFS('Danh sách thay đổi'!$H$5:$H$33,"Dễ",'Danh sách thay đổi'!$K$5:$K$33,"☑") -> 0
A40: Trung bình | B40: =COUNTIF('Danh sách thay đổi'!$H$5:$H$33,"Trung bình") -> 7 | C40: =COUNTIFS('Danh sách thay đổi'!$H$5:$H$33,"Trung bình",'Danh sách thay đổi'!$J$5:$J$33,"☑") -> 7 | D40: =COUNTIFS('Danh sách thay đổi'!$H$5:$H$33,"Trung bình",'Danh sách thay đổi'!$K$5:$K$33,"☑") -> 0
A41: Khó | B41: =COUNTIF('Danh sách thay đổi'!$H$5:$H$33,"Khó") -> 3 | C41: =COUNTIFS('Danh sách thay đổi'!$H$5:$H$33,"Khó",'Danh sách thay đổi'!$J$5:$J$33,"☑") -> 2 | D41: =COUNTIFS('Danh sách thay đổi'!$H$5:$H$33,"Khó",'Danh sách thay đổi'!$K$5:$K$33,"☑") -> 0
A43: THEO NGƯỜI PHỤ TRÁCH (đề xuất)
A44: Thành viên | B44: Số hạng mục | C44: Đã đồng ý | D44: Đã cập nhật
A45: Hòa | B45: =COUNTIF('Danh sách thay đổi'!$I$5:$I$33,"*Hòa*") -> 1 | C45: =COUNTIFS('Danh sách thay đổi'!$I$5:$I$33,"*Hòa*",'Danh sách thay đổi'!$J$5:$J$33,"☑") -> 1 | D45: =COUNTIFS('Danh sách thay đổi'!$I$5:$I$33,"*Hòa*",'Danh sách thay đổi'!$K$5:$K$33,"☑") -> 0
A46: Tuấn | B46: =COUNTIF('Danh sách thay đổi'!$I$5:$I$33,"*Tuấn*") -> 24 | C46: =COUNTIFS('Danh sách thay đổi'!$I$5:$I$33,"*Tuấn*",'Danh sách thay đổi'!$J$5:$J$33,"☑") -> 21 | D46: =COUNTIFS('Danh sách thay đổi'!$I$5:$I$33,"*Tuấn*",'Danh sách thay đổi'!$K$5:$K$33,"☑") -> 0
...

Sheet Danh sách thay đổi
A1: Danh sách thay đổi cần nhóm duyệt
A2: Cách dùng: đọc cột "Đặc tả chi tiết", rồi chọn ☑ ở cột "Nhóm đồng ý" nếu cả nhóm đồng ý (bấm vào ô → chọn từ danh sách). Sau khi sửa xong tài liệu/code thì tick cột "Đã cập nhật xong". Chỗ khó có mã G… ở cột cuối: bấm vào để xem giải thích và ví dụ ở sheet "Giải thích".
A4: Mã | B4: Phân hệ | C4: Hạng mục thay đổi | D4: Loại | E4: Đặc tả chi tiết (làm gì) | F4: Vì sao cần | G4: Mức độ | H4: Độ khó | I4: Phụ trách đề xuất | J4: Nhóm đồng ý | K4: Đã cập nhật xong | L4: Ghi chú của nhóm | M4: Xem giải thích
A5: T01 | B5: Xác thực & hồ sơ | C5: POST /api/auth/forgot-password | D5: Thêm mới | E5: Body: {"email": "..."} 1) Tìm User theo email. 2) Nếu có: tạo mã ngẫu nhiên, lưu hash vào PasswordResetToken.token_hash, hạn 15–30 phút, gửi email chứa link. 3) Dù email có tồn tại hay không đều trả CÙNG một thông báo. | F5: Bảng PasswordResetToken đã thiết kế nhưng chưa có endpoint nào dùng. Trả cùng thông báo để người lạ không dò được email nào đã đăng ký. | G5: Bắt buộc | H5: Khó | I5: Tuấn | J5: ☑ | K5: ☐ | L5: Tìm User theo email | M5: G2
A6: T02 | B6: Xác thực & hồ sơ | C6: POST /api/auth/reset-password | D6: Thêm mới | E6: Body: {"token": "...", "new_password": "..."} Băm token nhận được → tìm dòng khớp token_hash → kiểm tra chưa quá expires_at và used_at còn trống → đổi User.hashed_password, ghi used_at, vô hiệu các token cũ chưa dùng của tài khoản. | F6: Hoàn tất luồng quên mật khẩu. Mỗi mã chỉ dùng một lần và có hạn. | G6: Bắt buộc | H6: Trung bình | I6: Tuấn | J6: ☑ | K6: ☐ | M6: G2
A7: T03 | B7: Xác thực & hồ sơ | C7: POST /api/me/change-password | D7: Thêm mới | E7: Body: {"current_password": "...", "new_password": "..."} Sai mật khẩu hiện tại → 400/401. Không trả mật khẩu trong response. | F7: Người đã đăng nhập cần đổi mật khẩu mà không phải qua email. | G7: Nên có | H7: Dễ | I7: Tuấn | J7: ☑ | K7: ☐
A8: T04 | B8: Xác thực & hồ sơ | C8: Ảnh đại diện: PATCH /api/me nhận avatar_url; POST /api/me/avatar (upload) | D8: Thêm mới | E8: Giai đoạn 1: PATCH /api/me cho sửa full_name và avatar_url (nhập đường dẫn ảnh). Giai đoạn 2 (tùy chọn): POST /api/me/avatar nhận file ảnh, lưu và cập nhật avatar_url. | F8: Cột User.avatar_url đã có và trang Profile có ảnh đại diện nhưng chưa có cách đặt ảnh. | G8: Tùy chọn | H8: Trung bình | I8: Tuấn | J8: ☑ | K8: ☐ | L8: giai đoạn 2 upload avata
A9: T05 | B9: Tóm tắt hồ sơ | C9: GET /api/me/summary | D9: Thêm mới | E9: Trả số liệu cho trang Profile, ví dụ: {"ongoing_courses":3, "completed_courses":5, "known_skills":8, "ongoing_paths":1} Đếm từ StudentCourse, UserSkill (status=known), LearningPath (status=ongoing). | F9: Không có endpoint này thì trang Profile phải gọi 4 endpoint khác nhau chỉ để hiện 4 con số. | G9: Nên có | H9: Dễ | I9: Tuấn | J9: ☑ | K9: ☐ | L9: Trả số liệu cho trang Profile, ví dụ: {"ongoing_courses":3, "completed_courses":5, "known_skills":8, "ongoing_paths":1} (làm bình thường) Đếm từ StudentCourse, UserSkill (status=known), LearningPath (status=ongoing).(nhóm chưa chốt)
A10: T06 | C10: Chốt body của PATCH /api/me/skills | D10: Chốt quy tắc | E10: {"add":[{"skill_id":12,"status":"known"}], "update":[{"skill_id":5,"status":"learning"}], "remove":[7]} - status ∈ learning | known. - Ba khóa đều tùy chọn thời điểm đăng ký. - Làm trong MỘT transaction: lỗi một phần thì hủy cả request. - Kiểm tra skill_id có trong bảng Skill. - add một kỹ năng đã có = cập nhật (upsert). | F10: Spec chỉ ghi "thêm, cập nhật hoặc xóa" bằng một PATCH nhưng chưa nói gửi dữ liệu thế nào; frontend và backend sẽ làm lệch nhau. | G10: Bắt buộc | H10: Trung bình | I10: Tuấn | J10: ☑ | K10: ☐ | M10: G3
A11: T07 | B11: Xác thực & hồ sơ | C11: GET /api/me/skills hỗ trợ ?status=known|learning | D11: Sửa | E11: Thêm bộ lọc status. Lộ trình chỉ coi nút là xong khi kỹ năng ở trạng thái known nên cần lọc nhanh. | F11: UserSkill.status có 2 giá trị nhưng endpoint chưa cho lọc. | G11: Nên có | H11: Dễ | I11: Tuấn | J11: ☑ | K11: ☐
A12: T08 | B12: Xác thực & hồ sơ | C12: GET /api/me/courses?status=abandoned | D12: Thêm mới | E12: Trả các khóa học đã bỏ. Danh sách mặc định vẫn loại abandoned. | F12: §4 nói khóa đã bỏ xem được qua "bộ lọc lịch sử" nhưng bảng §2 chỉ có 3 bộ lọc (ongoing, bookmarked, completed). | G12: Bắt buộc | H12: Dễ | I12: Tuấn | J12: ☑ | K12: ☐
A13: T09 | B13: Xác thực & hồ sơ | C13: register không nhận role từ client | D13: Chốt quy tắc | E13: POST /api/auth/register luôn tạo role = student. Tài khoản admin chỉ tạo bằng scripts/create_admin.py. PATCH /api/me không cho sửa role. | F13: Nếu client gửi được role thì ai cũng tự thành admin (lỗ hổng bảo mật). | G13: Bắt buộc | H13: Dễ | I13: Tuấn | J13: ☑ | K13: ☐
A14: T10 | B14: Giao diện | C14: Sửa mẫu trang Profile | D14: Sửa | E14: Ô email chuyển thành chỉ đọc (nếu chọn D06 = A). Thêm nút "Đổi mật khẩu" và liên kết "Quên mật khẩu" ở trang đăng nhập. | F14: Mẫu hiện cho sửa email nhưng PATCH /api/me chưa hỗ trợ đổi email. | G14: Nên có | H14: Dễ | I14: Tuấn | J14: ☑ | K14: ☐
A15: T11 | B15: Ôn tập | C15: Đổi 4 endpoint ôn tập từ "theo kỹ năng" sang "theo khóa học" | D15: Sửa | E15: GET /api/skills/{id}/review → GET /api/courses/{course_id}/review POST /api/skills/{id}/review-attempts → POST /api/courses/{course_id}/review-attempts Giữ nguyên: GET /api/review-attempts/{id}, POST .../submit. | F15: ReviewAttempt chỉ lưu student_course_id (không có skill_id), và §2/§4 nói hoàn thành bài ôn tập đánh dấu KHÓA HỌC completed. Endpoint theo kỹ năng không cho biết khóa nào cần đánh dấu. | G15: Bắt buộc | H15: Trung bình | I15: Tuấn | J15: ☑ | K15: ☐ | M15: G1
A16: T12 | B16: Ôn tập | C16: Xóa GET/PATCH /api/me/skills khỏi §10 | D16: Xóa | E16: Hai endpoint này đã có ở §2 (Hòa làm). Ở §10 chỉ ghi chú: "xem §2". | F16: Trùng lặp: hai người cùng làm một endpoint sẽ xung đột khi merge. | G16: Bắt buộc | H16: Dễ | I16: Tuấn | J16: ☐ | K16: ☐
A17: T13 | B17: Ôn tập | C17: Nộp bài chạy trong MỘT transaction | D17: Chốt quy tắc | E17: POST .../submit khi đạt (passed = true): 1) Chấm từng câu, ghi ReviewAnswer. 2) Ghi score_percent, passed. 3) StudentCourse.status → completed, ghi completed_at. 4) Thêm/cập nhật UserSkill (known) cho MỌI kỹ năng của khóa (qua CourseSkillRelation). 5) Kiểm tra lại các LearningPath đang ongoing có chứa các kỹ năng đó. Bước nào lỗi thì hủy toàn bộ.(tạm thời chưa quyết định) 6) SAU KHI commit thành công: trả kết quả (score_percent, passed) cho học viên ngay, rồi mới chạy nền gửi email kết quả (T29). Gửi email KHÔNG nằm trong transaction; gửi lỗi không hủy bài đã lưu. | F17: Nếu không dùng transaction, lỗi giữa chừng làm khóa "completed" nhưng hồ sơ kỹ năng chưa cập nhật (dữ liệu lệch). | G17: Bắt buộc | H17: Khó | I17: Tuấn + Hòa + Tâm | J17: ☑ | K17: ☐ | L17: 5) Kiểm tra lại các LearningPath đang ongoing có chứa các kỹ năng đó. Bước nào lỗi thì hủy toàn bộ.(tạm thời chưa quyết định) | M17: G4
A18: T14 | B18: Ôn tập | C18: Chọn 20 câu và tạo sẵn 20 dòng ReviewAnswer khi bắt đầu | D18: Chốt quy tắc | E18: POST .../review-attempts: lấy 60 câu ngẫu nhiên từ Question của các kỹ năng khóa đó dạy (is_active = true), chia đều giữa các kỹ năng, ghi sẵn 20 câu random ReviewAnswer (position 1–20, chưa có selected_index). | F18: Server biết chính xác 20 câu cần chấm; client không thể gửi câu hỏi bừa hay lấy câu dễ. | G18: Bắt buộc | H18: Trung bình | I18: Tuấn | J18: ☑ | K18: ☐ | M18: G5
A19: T15 | B19: Ôn tập | C19: Không lộ đáp án trước khi nộp; chỉ chủ sở hữu xem attempt | D19: Chốt quy tắc | E19: Trước khi nộp: KHÔNG trả correct_index và explanation ở bất kỳ endpoint nào. Attempt của người khác → trả 404 (không phải 403, để không lộ sự tồn tại). | F19: Người dùng mở công cụ nhà phát triển trên trình duyệt là thấy hết dữ liệu API trả về. | G19: Bắt buộc | H19: Dễ | I19: Tuấn | J19: ☑ | K19: ☐ | L19: (user làm hết câu hỏi rồi trả về đáp án ) | M19: G9
A20: T16 | B20: Ôn tập | C20: Điều kiện bắt đầu và lỗi 409 | D20: Chốt quy tắc | E20: - Chưa có StudentCourse hoặc chưa ongoing → 409 (hướng dẫn bấm "Tham gia"). - Khóa đã completed → 409 (trừ khi D10 chọn cho ôn lại). - Nộp lần hai → 409. - Câu bỏ trống tính là sai. | F20: §10 chưa nói rõ khi nào được/không được làm bài. | G20: Bắt buộc | H20: Dễ | I20: Tuấn | J20: ☐ | K20: ☐
A21: T17 | B21: Ôn tập | C21: review-history: bộ lọc và phân trang | D21: Sửa | E21: GET /api/me/review-history hỗ trợ ?course_id=, ?passed=true|false, ?page=&page_size=. | F21: Danh sách sẽ dài dần theo số lần làm bài; trang Profile cần lọc theo khóa. | G21: Nên có | H21: Dễ | I21: Tuấn | J21: ☑ | K21: ☐
A22: T18 | B22: Ôn tập | C22: Cập nhật trạng thái LearningPath sau khi ôn tập đạt | D22: Chốt quy tắc | E22: Sau khi UserSkill được cập nhật, nếu mọi nút bắt buộc (is_required = true) của một lộ trình ongoing đều có kỹ năng known thì LearningPath.status → completed. Viết thành một hàm trong learning_path_service để Tuấn gọi. | F22: Spec định nghĩa completed = mọi nút bắt buộc đã xong, nhưng chưa nói ai và lúc nào cập nhật. | G22: Nên có | H22: Khó | I22: Tâm | J22: ☐ | K22: ☐ | M22: G8
A23: T19 | B23: Quản trị | C23: CRUD ngân hàng câu hỏi: /api/admin/questions | D23: Thêm mới | E23: GET (lọc ?skill_id=, kèm số câu của từng kỹ năng), POST, GET /{id}, PATCH /{id}, DELETE /{id}. POST body: skill_id, content, options (đúng 4 đáp án), correct_index (0–3), explanation. | F23: Bảng Question không có endpoint quản trị nên chỉ nạp được bằng seed. Mỗi kỹ năng cần ≥ 20 câu mới có bài ôn tập. | G23: Bắt buộc | H23: Trung bình | I23: Tuấn | J23: ☑ | K23: ☐ | M23: G6
A24: T20 | B24: Quản trị | C24: DELETE question: xóa hoặc vô hiệu hóa | D24: Chốt quy tắc | E24: Chưa từng dùng trong bài nào → xóa thật. Đã có ReviewAnswer tham chiếu → đặt is_active = false (ẩn khỏi bài mới, giữ lịch sử). | F24: Khóa ngoại ReviewAnswer → Question là RESTRICT nên không xóa được câu đã dùng. | G24: Nên có | H24: Dễ | I24: Tuấn | J24: ☑ | K24: ☐ | M24: G6
A25: T21 | B25: Quản trị | C25: POST /api/admin/questions/import (nhập hàng loạt) | D25: Thêm mới | E25: Nhận file CSV/JSON. Kiểm tra: skill_id tồn tại, đúng 4 đáp án, correct_index 0–3. Trả báo cáo số dòng thành công/lỗi. | F25: Nhập tay hàng trăm câu hỏi là rất chậm. | G25: Tùy chọn | H25: Trung bình | I25: Tuấn | J25: ☑ | K25: ☐
A26: T22 | B26: Phản hồi & liên hệ | C26: POST /api/feedback | D26: Thêm mới | E26: Body: target_type (course|system), course_id (bắt buộc khi course, để trống khi system), feedback_type, content. user_id lấy từ tài khoản đăng nhập. | F26: Bảng Feedback có sẵn cho màn hình "Liên hệ & góp ý" nhưng chưa có endpoint. | G26: Bắt buộc | H26: Dễ | I26: Tâm | J26: ☐ | K26: ☐ | M26: G7
A27: T23 | B27: Phản hồi & liên hệ | C27: GET /api/courses/{course_id}/contact | D27: Thêm mới | E27: Trả instructor (từ Course) và contact_email, contact_phone (từ CourseContact; có thể rỗng). | F27: Khung "Thông tin liên hệ của khóa học" cạnh form phản hồi. | G27: Bắt buộc | H27: Dễ | I27: Tâm | J27: ☐ | K27: ☐
A28: T24 | B28: Phản hồi & liên hệ | C28: GET /api/admin/feedback | D28: Thêm mới | E28: Admin xem phản hồi; lọc theo target_type, course_id; phân trang. | F28: Phản hồi gửi đi phải có chỗ để admin đọc. | G28: Nên có | H28: Dễ | I28: Tâm | J28: ☐ | K28: ☐
A29: T25 | B29: Phản hồi & liên hệ | C29: PATCH /api/admin/courses/{course_id}/contact | D29: Thêm mới | E29: Admin nhập hoặc sửa email, số điện thoại liên hệ (tạo dòng CourseContact nếu chưa có). | F29: Dataset không có email/số điện thoại nên cần nhập tay. | G29: Nên có | H29: Dễ | I29: Tâm | J29: ☐ | K29: ☐
A30: T26 | B30: Cơ sở dữ liệu | C30: Thêm Question.is_active | D30: Sửa | E30: is_active BOOLEAN NOT NULL DEFAULT TRUE. Bài ôn tập chỉ lấy câu is_active = true. | F30: Cho phép ẩn câu hỏi đã dùng thay vì xóa. | G30: Nên có | H30: Dễ | I30: Tuấn | J30: ☑ | K30: ☐ | M30: G6
A31: T27 | B31: Cơ sở dữ liệu | C31: Thêm ReviewAttempt.submitted_at | D31: Sửa | E31: submitted_at TIMESTAMP NULL. attempted_at = lúc bắt đầu, submitted_at = lúc nộp. Rỗng = đang làm dở. | F31: Hiện chỉ có attempted_at nên không phân biệt được lúc bắt đầu và lúc nộp. | G31: Tùy chọn | H31: Dễ | I31: Tuấn | J31: ☐ | K31: ☐
A32: T28 | B32: Cấu hình | C32: Thêm biến môi trường | D32: Sửa | E32: SMTP_HOST, SMTP_PORT, SMTP_USER, SMTP_PASSWORD, FRONTEND_URL, RESET_TOKEN_EXPIRE_MINUTES, REVIEW_PASS_PERCENT → .env.example và SETUP.md. | F32: Gửi email quên mật khẩu cần SMTP; điểm đạt đọc từ cấu hình để đổi không cần sửa code. | G32: Bắt buộc | H32: Dễ | I32: Tuấn | J32: ☑ | K32: ☐
A33: T29 | B33: Ôn tập | C33: Gửi email kết quả sau khi nộp bài | D33: Thêm mới | E33: Thứ tự trong POST /api/review-attempts/{attempt_id}/submit: 1) Chấm điểm và lưu toàn bộ trong MỘT transaction (T13), commit. 2) Trả ngay score_percent, passed, số câu đúng cho học viên. 3) SAU ĐÓ chạy nền (FastAPI BackgroundTasks) gửi email tới User.email: tên khóa học, điểm %, Đạt/Không đạt (ngưỡng REVIEW_PASS_PERCENT), số câu đúng/20, thời gian nộp, link FRONTEND_URL/review/history/{attempt_id}. 4) Gửi lỗi → chỉ ghi log; KHÔNG rollback, KHÔNG trả lỗi cho người dùng. Dùng chung module app/core/email.py (send_email) với luồng quên mật khẩu. | F33: Học viên có bản lưu kết quả trong hộp thư. Tách khỏi transaction để máy chủ email chậm/lỗi không làm mất bài và không bắt học viên chờ. | G33: Nên có | H33: Dễ | I33: Tuấn | J33: ☑ | K33: ☐ | L33: lưu xong → trả điểm ngay → rồi mới gửi email. Còn chốt: email có kèm đáp án không ( không),( chỉ gửi link Khóa Học nào Đậu/ Rớt + Điểm); gửi mọi lần hay chỉ khi đạt (đề xuất: mọi lần). | M33: G4

Sheet Quyết định cần chốt
A1: Quyết định cần nhóm chốt
A2: Mỗi dòng là một câu hỏi mà tài liệu hiện chưa trả lời. Cả nhóm thống nhất → chọn A / B / Khác ở cột "Nhóm chọn" → tick ☑ "Đã chốt". Nếu chọn "Khác" hoặc cần ghi con số cụ thể thì viết vào cột "Ghi chú".
A4: Mã | B4: Câu hỏi cần chốt | C4: Bối cảnh (nói đơn giản) | D4: Phương án A | E4: Phương án B | F4: Đề xuất | G4: Nếu chọn thì ảnh hưởng gì | H4: Nhóm chọn | I4: Đã chốt | J4: Ghi chú / giá trị cụ thể | K4: Liên quan
A5: D01 | B5: Ôn tập tính THEO KHÓA HỌC hay THEO KỸ NĂNG? | C5: Bài ôn tập đánh dấu cả khóa học là hoàn thành, nhưng khóa học có thể dạy nhiều kỹ năng. | D5: A. Theo khóa học: đường dẫn /api/courses/{course_id}/review…; 20 câu lấy từ các kỹ năng của khóa. | E5: B. Theo kỹ năng: giữ đường dẫn /api/skills/{id}/review…, thêm cột skill_id vào ReviewAttempt, body bắt buộc có course_id. | F5: A | G5: A: sửa 4 đường dẫn, DB giữ nguyên. B: sửa DB và vẫn phải trả lời "khóa dạy 3 kỹ năng thì ôn kỹ năng nào để completed". | H5: A | I5: ☑ | K5: T11, T12, T14
A6: D02 | B6: Điểm đạt tối thiểu là bao nhiêu phần trăm? | C6: Spec chỉ nói "theo chính sách hoàn thành đã thống nhất", chưa có con số. Cột passed lưu kết quả đạt/không đạt. | D6: A. 70% | E6: B. 80% (hoặc giá trị khác: ghi vào cột Ghi chú và chọn "Khác") | F6: A | G6: Chọn giá trị rồi đặt vào biến REVIEW_PASS_PERCENT. Đổi mức đạt sau này không làm thay đổi kết quả cũ vì passed đã được lưu riêng. (Con số 70/80 chỉ để minh họa.) | H6: Khác | I6: ☑ | J6: >=60 Đậu | K6: T13, T28
A7: D03 | B7: Được làm lại bài ôn tập không? Có tiếp tục bài đang dở không? | C7: Mỗi lần làm bài là một dòng ReviewAttempt mới. | D7: A. Làm lại không giới hạn; mỗi khóa chỉ có tối đa một bài đang dở (bắt đầu lại thì trả bài dở đó). | E7: B. Giới hạn số lần hoặc phải chờ một khoảng thời gian giữa hai lần. | F7: A | G7: B cần thêm đếm số lần và kiểm tra thời gian trong review_service. | H7: A | I7: ☑ | K7: T16
A8: D04 | B8: 20 câu lấy từ đâu khi khóa dạy nhiều kỹ năng? | C8: Question gắn với từng kỹ năng. Tài liệu DB ghi "mỗi kỹ năng cần ≥ 20 câu". | D8: A. Gộp câu hỏi của tất cả kỹ năng khóa dạy, tổng ≥ 20; chia đều giữa các kỹ năng. | E8: B. Mỗi kỹ năng phải đủ 20 câu riêng (khóa dạy 3 kỹ năng cần 60 câu). | F8: A | G8: B đòi ngân hàng câu hỏi lớn hơn nhiều; A dễ đạt điều kiện "có bài ôn tập" hơn. | H8: A | I8: ☑ | J8: (tự tạo gent ai) | K8: T14, T19
A9: D05 | B9: UserSkill.status = "learning" được đặt khi nào? | C9: Cột có 2 giá trị learning và known nhưng spec chưa nói ai đặt "learning". | D9: A. Khi bấm Tham gia khóa (join): thêm các kỹ năng của khóa ở trạng thái learning (nếu chưa known). | E9: B. Chỉ người dùng tự đặt thủ công qua PATCH /api/me/skills. | F9: A | G9: A: sửa thêm logic trong endpoint join (Hòa). B: đơn giản hơn nhưng trạng thái learning hiếm khi có dữ liệu. | H9: A | I9: ☑ | K9: T06
A10: D06 | B10: Cho phép đổi email không? | C10: Email là tên đăng nhập và duy nhất. Đổi email thường cần xác thực email mới. | D10: A. Không cho đổi email (ô email chỉ đọc). | E10: B. Cho đổi, kèm bước gửi mã xác nhận tới email mới. | F10: A | G10: B cần thêm bảng/endpoint xác thực email. | H10: A | I10: ☑ | K10: T10
A11: D07 | B11: Ảnh đại diện: upload hay chỉ nhập URL? | C11: User.avatar_url lưu đường dẫn ảnh. | D11: A. Chỉ nhập URL (làm trước). | E11: B. Tải file lên server (cần nơi lưu file, giới hạn dung lượng, định dạng). | F11: A | G11: B làm sau nếu còn thời gian. | H11: B | I11: ☑ | K11: T04
A12: D08 Tự quyêt | B12: Đăng xuất hoạt động thế nào? | C12: POST /api/auth/logout cần có nghĩa cụ thể. | D12: A. Token không lưu trạng thái (JWT): đăng xuất = client xóa token, server trả 200. | E12: B. Server lưu danh sách token bị thu hồi (cần thêm bảng). | F12: A | G12: B an toàn hơn nhưng thêm bảng và kiểm tra ở mỗi request. | H12: A | I12: ☑
A13: D09 Y | B13: Có làm quên mật khẩu trong phiên bản đầu không? | C13: Cần gửi email thật (SMTP), thêm 2 endpoint và 2 trang giao diện. | D13: A. Có làm (T01, T02, T28). | E13: B. Hoãn: bỏ bảng PasswordResetToken khỏi bản đầu, ghi vào danh sách làm sau. | F13: A nếu còn thời gian | G13: Nếu chọn B thì hạ T01, T02 xuống "Tùy chọn" và bỏ model password_reset_token. | H13: A | I13: ☑ | K13: T01, T02, T28
A14: D10 Y | B14: Khóa đã completed có cho ôn lại không? | C14: completed là trạng thái cuối, nhưng người học có thể muốn luyện lại. | D14: A. Không: bắt đầu bài mới trả 409. | E14: B. Có: cho làm lại, kết quả mới chỉ lưu thêm vào lịch sử, không đổi completed. | F14: A | G14: B cần bỏ kiểm tra ở T16. | H14: B | I14: ☑ | K14: T16
A15: D11 không làm | B15: Danh sách "Loại phản hồi" (feedback_type)? | C15: Ô "Loại phản hồi" trong màn hình góp ý cần danh sách lựa chọn. | D15: A. Danh sách cố định theo từng nhóm: khóa học (ví dụ Nội dung bài giảng, Giảng viên, Link khóa học lỗi), hệ thống (Lỗi, Đề xuất tính năng). | E15: B. Nhập tự do. | F15: A | G15: Nhóm liệt kê danh sách cụ thể vào cột Ghi chú. | H15: A | I15: ☑ | K15: T22

Sheet Giải thích
A1: Giải thích những chỗ khó
A2: Mỗi mục giải thích một chỗ khó bằng lời đơn giản, có ví dụ và các bước làm. Mã G… tương ứng cột "Xem giải thích" ở sheet "Danh sách thay đổi".
A4: Mã | B4: Chủ đề | C4: Vấn đề là gì (nói đơn giản) | D4: Ví dụ minh họa | E4: Cách xử lý đề xuất (các bước) | F4: Liên quan
A5: G1 | B5: Ôn tập theo khóa học hay kỹ năng | C5: Bài ôn tập kết thúc bằng việc đánh dấu KHÓA HỌC là completed. Nhưng endpoint hiện tại nói về KỸ NĂNG, và bảng ReviewAttempt không có cột skill_id. | D5: Khóa "Python for Everybody" dạy 3 kỹ năng: Python, SQL, Cấu trúc dữ liệu. Học viên gọi POST /api/skills/1/review-attempts (kỹ năng Python) và đạt 85%. → Hệ thống ghi một dòng ReviewAttempt nhưng không biết dòng đó thuộc khóa nào, cũng không biết là ôn kỹ năng nào. | E5: Đưa course_id lên đường dẫn: POST /api/courses/{course_id}/review-attempts. Hệ thống tìm StudentCourse của (người dùng, khóa), tạo ReviewAttempt gắn student_course_id, lấy câu hỏi từ các kỹ năng của khóa. Từ node lộ trình: người dùng chọn kỹ năng → xem khóa gợi ý → tham gia khóa → ôn tập theo khóa. | F5: T11, T12, D01
A6: G2 | B6: Luồng quên mật khẩu | C6: Người dùng không đăng nhập được nên phải chứng minh mình sở hữu email. Hệ thống gửi một đường link có mã dùng một lần. | D6: Bình nhập email a@x.com → nhận email có link .../reset?token=Ab12… → mở link, nhập mật khẩu mới. | E6: 1) Bình nhập email → POST /api/auth/forgot-password. 2) Server tạo mã ngẫu nhiên, lưu BẢN BĂM vào PasswordResetToken (hạn 15–30 phút), gửi mã gốc qua email. 3) Server luôn trả cùng thông báo ("Nếu email đúng, bạn sẽ nhận được hướng dẫn"). 4) Bình mở link, nhập mật khẩu mới → POST /api/auth/reset-password. 5) Server băm mã nhận được, tìm token_hash khớp, kiểm tra chưa hết hạn và used_at còn trống. 6) Hợp lệ → đổi hashed_password, ghi used_at, vô hiệu mã cũ. Vì sao lưu bản băm: nếu lộ CSDL, kẻ xấu cũng không dùng được mã. | F6: T01, T02, D09
A7: G3 | B7: Cách gửi dữ liệu cho PATCH /api/me/skills | C7: Một PATCH phải làm được ba việc: thêm, sửa, xóa. Nếu không chốt dạng dữ liệu, frontend và backend mỗi bên hiểu một kiểu. | D7: Học viên bỏ kỹ năng "SQL", thêm "Docker" (đã biết), đổi "Python" từ learning sang known: { "add": [{"skill_id": 40, "status": "known"}], "update": [{"skill_id": 1, "status": "known"}], "remove": [2] } | E7: Chạy cả ba việc trong một transaction. Nếu skill_id 40 không tồn tại thì hủy luôn việc sửa và xóa, trả lỗi rõ ràng. add một kỹ năng đã có → coi như cập nhật, không báo lỗi trùng. | F7: T06
A8: G4 | B8: Vì sao nộp bài phải dùng transaction | C8: Nộp bài làm nhiều việc liên tiếp trên nhiều bảng. Nếu dừng giữa chừng, dữ liệu sẽ mâu thuẫn. | D8: Học viên đạt 17/20 = 85%. Bước 3 đã đánh dấu khóa completed. Bước 4 ghi UserSkill thì mất kết nối → khóa đã hoàn thành nhưng hồ sơ kỹ năng trống; lộ trình không bao giờ nhận kỹ năng đó. | E8: Gói các bước vào một transaction: 1) Ghi ReviewAnswer (selected_index, is_correct). 2) Tính và ghi score_percent, passed. 3) Nếu passed: StudentCourse → completed + completed_at. 4) Upsert UserSkill (known) cho từng kỹ năng của khóa. 5) Gọi hàm kiểm tra hoàn thành lộ trình (T18). Lỗi ở bất kỳ bước nào → rollback toàn bộ, trả lỗi. | F8: T13, T18
A9: G5 | B9: Chọn 20 câu và tạo sẵn ReviewAnswer | C9: Khi bắt đầu bài, server nên quyết định luôn 20 câu nào và lưu lại, thay vì để client tự báo câu nào đã làm. | D9: Khóa dạy 3 kỹ năng: Python, SQL, Dữ liệu. Chọn 7 + 7 + 6 câu ngẫu nhiên (is_active = true), trộn thứ tự. Ghi 20 dòng ReviewAnswer: position 1…20, selected_index rỗng. | E9: 1) Gom Question của các kỹ năng khóa dạy (qua CourseSkillRelation). 2) Nếu tổng < 20 → GET .../review trả available = false, lý do "thiếu câu hỏi". 3) Chia đều theo kỹ năng, lấy ngẫu nhiên. 4) Tạo ReviewAttempt + 20 ReviewAnswer trong một transaction. 5) Khi nộp, chỉ chấm đúng 20 dòng đã tạo; câu_id lạ bị bỏ qua hoặc báo lỗi. | F9: T14, D04
A10: G6 | B10: Quản trị câu hỏi và is_active | C10: Admin phải thêm/sửa câu hỏi được. Nhưng câu đã xuất hiện trong bài của học viên thì không xóa thẳng được, vì lịch sử ôn tập còn tham chiếu tới nó. | D10: Câu #50 đã nằm trong 120 lần làm bài. Admin bấm Xóa → CSDL từ chối (RESTRICT) vì còn 120 dòng ReviewAnswer trỏ tới. | E10: Thêm cột is_active. DELETE /api/admin/questions/{id}: - Chưa từng dùng → xóa thật. - Đã dùng → is_active = false: không xuất hiện trong bài mới, nhưng lịch sử cũ vẫn xem được. Danh sách admin hiển thị số câu còn hoạt động theo kỹ năng để biết kỹ năng nào chưa đủ 20 câu. | F10: T19, T20, T26
A11: G7 | B11: Ràng buộc của bảng Feedback | C11: Phản hồi có thể về MỘT KHÓA HỌC hoặc về HỆ THỐNG. Hai trường target_type và course_id phải khớp nhau. | D11: Hợp lệ: target_type = course, course_id = 15. Hợp lệ: target_type = system, course_id = rỗng. KHÔNG hợp lệ: course nhưng course_id rỗng; hoặc system nhưng có course_id. | E11: CSDL đã có CHECK: (target_type = course AND course_id IS NOT NULL) OR (target_type = system AND course_id IS NULL). Backend kiểm tra cùng quy tắc ở schema để trả lỗi 422 dễ hiểu thay vì lỗi CSDL. | F11: T22
A12: G8 | B12: Khi nào lộ trình được coi là hoàn thành | C12: Lộ trình completed khi mọi nút BẮT BUỘC đã xong (kỹ năng known). Nút tùy chọn không tính. | D12: Lộ trình 7 nút: 5 nút is_required = true, 2 nút tùy chọn. Học viên ôn đạt kỹ năng thứ 5 trong 5 nút bắt buộc → lộ trình chuyển completed dù 2 nút tùy chọn chưa xong. | E12: Sau khi UserSkill cập nhật (bước 5 của G4), tìm các LearningPath ongoing của học viên có chứa các kỹ năng vừa đạt; đếm nút is_required chưa known; nếu = 0 thì đặt status = completed. Dùng cột is_required (đã có ở LearningPathNode). | F12: T18
A13: G9 | B13: Không lộ đáp án trước khi nộp bài | C13: Mọi dữ liệu API trả về đều xem được bằng công cụ nhà phát triển của trình duyệt, kể cả những phần giao diện không hiển thị. | D13: Nếu response câu hỏi có {"content": "...", "options": [...], "correct_index": 2} thì ai cũng thấy đáp án đúng là câu 3. | E13: Schema trả về khi làm bài chỉ có question_id, content, options, position. correct_index và explanation chỉ xuất hiện ở GET /api/me/review-history/{attempt_id} SAU KHI đã nộp. Kiểm thử: gọi GET attempt chưa nộp và kiểm tra response không có hai trường này. | F13: T15

Sheet Endpoint (bản mới)
A1: Bảng endpoint bản mới (§2, §10 và phần bổ sung)
A2: Trạng thái: MỚI = thêm; SỬA = đổi đường dẫn hoặc quy tắc; BỎ = xóa khỏi mục này; Giữ = không đổi. Cột "Đã làm xong": tick khi backend đã chạy được endpoint (và frontend đã gọi).
A4: Mục | B4: Method | C4: Endpoint | D4: Trạng thái | E4: Mô tả | F4: Dữ liệu gửi lên | G4: Dữ liệu trả về | H4: Lỗi thường gặp | I4: Quyền | J4: Phụ trách | K4: Đã làm xong
A5: §2 | B5: POST | C5: /api/auth/register | D5: Giữ (bổ sung) | E5: Đăng ký tài khoản mới. role luôn là student. | F5: email, password, full_name | G5: 201 + thông tin người dùng | H5: 409 email đã tồn tại; 422 dữ liệu sai | I5: Công khai | J5: Hòa | K5: ☐
A6: §2 | B6: POST | C6: /api/auth/login | D6: Giữ | E6: Đăng nhập. | F6: email, password | G6: 200 + access token + thông tin người dùng (gồm role) | H6: 401 sai thông tin | I6: Công khai | J6: Hòa | K6: ☐
A7: §2 | B7: POST | C7: /api/auth/logout | D7: Giữ | E7: Đăng xuất (xem D08). | F7: — | G7: 200 | H7: 401 | I7: Người dùng | J7: Hòa | K7: ☐
A8: §2 | B8: POST | C8: /api/auth/forgot-password | D8: MỚI | E8: Yêu cầu đặt lại mật khẩu qua email. | F8: email | G8: 200 + thông báo chung (luôn giống nhau) | H8: 422 | I8: Công khai | J8: Hòa | K8: ☐
A9: §2 | B9: POST | C9: /api/auth/reset-password | D9: MỚI | E9: Đặt mật khẩu mới bằng mã trong email. | F9: token, new_password | G9: 200 | H9: 400 mã sai/hết hạn/đã dùng | I9: Công khai | J9: Hòa | K9: ☐
A10: §2 | B10: GET | C10: /api/me | D10: Giữ | E10: Lấy hồ sơ người dùng đã đăng nhập. | F10: — | G10: user_id, email, full_name, avatar_url, role, created_at | H10: 401 | I10: Người dùng | J10: Hòa | K10: ☐
A11: §2 | B11: PATCH | C11: /api/me | D11: Giữ (bổ sung) | E11: Cập nhật hồ sơ. | F11: full_name, avatar_url (không có role, email) | G11: 200 hồ sơ mới | H11: 401; 422 | I11: Người dùng | J11: Hòa | K11: ☐
A12: §2 | B12: POST | C12: /api/me/avatar | D12: MỚI (tùy chọn) | E12: Tải ảnh đại diện lên. | F12: file ảnh | G12: 200 avatar_url | H12: 413 file quá lớn; 415 sai định dạng | I12: Người dùng | J12: Hòa | K12: ☐
A13: §2 | B13: POST | C13: /api/me/change-password | D13: MỚI | E13: Đổi mật khẩu khi đã đăng nhập. | F13: current_password, new_password | G13: 200 | H13: 400 sai mật khẩu hiện tại | I13: Người dùng | J13: Hòa | K13: ☐
A14: §2 | B14: GET | C14: /api/me/summary | D14: MỚI | E14: Số liệu tổng hợp cho trang Profile. | F14: — | G14: ongoing_courses, completed_courses, known_skills, ongoing_paths | H14: 401 | I14: Người dùng | J14: Hòa | K14: ☐
A15: §2 | B15: GET | C15: /api/me/skills | D15: Giữ (thêm ?status=) | E15: Kỹ năng trong hồ sơ. | F15: ?status=known|learning | G15: Danh sách {skill_id, skill, status, updated_at} | H15: 401 | I15: Người dùng | J15: Hòa | K15: ☐
... A40: Phản hồi | B40: PATCH | C40: /api/admin/courses/{course_id}/contact | D40: MỚI | E40: Admin nhập/sửa liên hệ khóa học. | F40: contact_email, contact_phone | G40: 200 | H40: 404; 403 | I40: Admin | J40: Khôi | K40: ☐

Sheet File cần sửa
A1: Các file khác bị ảnh hưởng
A2: Sau khi nhóm chốt, các tài liệu và file bên dưới cần cập nhật để khớp nhau. Tick ☑ khi đã sửa xong.
A4: STT | B4: Tài liệu / file | C4: Cần sửa gì | D4: Mức độ | E4: Phụ trách | F4: Đã sửa xong | G4: Ghi chú
A5: 1 | B5: docs/api-endpoints.md | C5: Thay §2 và §10 theo sheet Endpoint; thêm câu hỏi vào §11; thêm mục Phản hồi & liên hệ. | D5: Bắt buộc | E5: Tâm Tuấn | F5: ☐
A6: 2 | B6: docs/database-design.md | C6: Thêm Question.is_active; ReviewAttempt.submitted_at (nếu chọn); ghi chú cấu hình. | D6: Nên có | E6: Tuấn | F6: ☐
A7: 3 | B7: STRUCTURE.md (backend) | C7: Đổi đường dẫn review sang theo khóa học; thêm routers/admin/questions.py, routers/feedback.py; thêm models review_answer.py, password_reset_token.py, feedback.py, course_contact.py; đổi tên review_question.py → question.py, user_course.py → student_course.py cho khớp CSDL; thêm core/email.py (send_email dùng chung cho quên mật khẩu và email kết quả ôn tập). | D7: Bắt buộc | E7: Tuấn | F7: ☐
A8: 4 | B8: STRUCTURE.md (frontend) | C8: Thêm ForgotPasswordPage, ResetPasswordPage, ChangePasswordForm, AdminQuestionsPage, FeedbackPage; route ôn tập /review/:courseId; thêm feedback.api.js. | D8: Bắt buộc | E8: Tuấn | F8: ☐
A9: 5 | B9: TASKS.md | C9: Hòa: thêm forgot/reset/change-password/avatar/summary. Tuấn: thêm admin questions, đổi review theo khóa học. tâm: nhận feedback và contact. | D9: Bắt buộc | E9: Tuấn | F9: ☐
A10: 6 | B10: .env.example và SETUP.md | C10: Thêm SMTP_*, FRONTEND_URL, RESET_TOKEN_EXPIRE_MINUTES, REVIEW_PASS_PERCENT; hướng dẫn cấu hình email thử (ví dụ dùng dịch vụ SMTP thử nghiệm). | D10: Bắt buộc | E10: Tuấn | F10: ☐
A11: 7 | B11: init_structure.py | C11: Thêm các file mới (routers, models, pages ở trên) rồi chạy lại; script không ghi đè file đã có. | D11: Nên có | F11: ☐
A12: 8 | B12: Mẫu giao diện Profile | C12: Ô email chỉ đọc; thêm nút Đổi mật khẩu; liên kết Quên mật khẩu ở trang đăng nhập. | D12: Nên có | E12: Tuấn | F12: ☐
A13: 9 | B13: README.md | C13: Cập nhật bảng "Tổng quan API" (thêm ôn tập theo khóa học, phản hồi & liên hệ). | D13: Tùy chọn | E13: Tâm Tuấn | F13: ☐
